<?xml version="1.0" ?>
<robot name="physics">
    <link name="box">
        <visual>
            <geometry>
                <mesh filename="package://myrobot5/meshes/link1.dae" />
            </geometry>
            <origin xyz="0 0 0" />
            <material name="blue">
                <color rgba="0 0 0.8 1" />
            </material>
        </visual>
        <collision>
            <geometry>
                <mesh filename="package://myrobot5/meshes/link1.stl" />
            </geometry>
            <origin xyz="0 0 0" />
        </collision>        
        <inertial>
            <mass value="1" />
            <inertia ixx="1.0" ixy="0.0" ixz="0.0" iyy="1.0" iyz="0.0" izz="1.0" />
        </inertial>
    </link>
    <joint name="base_to_tail" type="fixed">
        <parent link="box" />
        <child link="tail" />
        <origin xyz="0 -1 0" />
        <axis xyz="0 1 0" />
    </joint>
    <link name="tail">
        <visual>
            <geometry>
                <mesh filename="package://myrobot5/meshes/link2.dae" />
            </geometry>
            <origin xyz="0 0 0" />
            <material name="blue">
                <color rgba="0 0 0.8 1" />
            </material>
            <inertial>
                <mass value="1" />
                <inertia ixx="1.0" ixy="0.0" ixz="0.0" iyy="1.0" iyz="0.0" izz="1.0" />
            </inertial>
        </visual>
        <collision>
            <geometry>
                <mesh filename="package://myrobot5/meshes/link2.stl" />
            </geometry>
        </collision>        
        <inertial>
            <mass value="0.1" />
            <inertia ixx="0.03" iyy="0.03" izz="0.03" ixy="0.0" ixz="0.0" iyz="0.0" />
        </inertial>
    </link>
    <link name="arm_1">
        <visual>
            <geometry>
                <mesh filename="package://myrobot5/meshes/link3.dae" />
            </geometry>
            <orgin rpy="0.0 0 0" xyz="0 0 0" />
            <material name="blue">
                <color rgba="0 0 0.8 1" />
            </material>
        </visual>
        <collision>
            <geometry>
                <mesh filename="package://myrobot5/meshes/link3.stl" />
            </geometry>
            <orgin rpy="0.0 0 0" xyz="0 0 0" />
        </collision>        
        <inertial>
            <mass value="1" />
            <inertia ixx="1.0" ixy="0.0" ixz="0.0" iyy="1.0" iyz="0.0" izz="1.0" />
        </inertial>
    </link>
    <joint name="base_to_arm" type="revolute">
        <parent link="box" />
        <child link="arm_1" />
        <origin rpy="0.0 0 0" xyz="0 0 0" />
        <axis xyz="0 1 0" />
        <limit effort="10.0" lower="0.0" upper="2.0" velocity="0.5" />
    </joint>
    <link name="arm_2">
        <visual>
            <geometry>
                <mesh filename="package://myrobot5/meshes/link3.dae" />
            </geometry>
            <orgin rpy="0.1 0 3.0" xyz="0 0 -.1" />
            <material name="blue">
                <color rgba="0 0 0.8 1" />
            </material>
        </visual>
        <collision>
            <geometry>
                <mesh filename="package://myrobot5/meshes/link3.stl" />
            </geometry>
            <orgin rpy="0.1 0 3.0" xyz="0 0 -.1" />
        </collision>
        <inertial>
            <mass value="1" />
            <inertia ixx="1.0" ixy="0.0" ixz="0.0" iyy="1.0" iyz="0.0" izz="1.0" />
        </inertial>
    </link>
    <joint name="base_to_arm2" type="revolute">
        <parent link="box" />
        <child link="arm_2" />
        <origin rpy="0.1 0 3.0" xyz="0 0 -.1" />
        <axis xyz="0 1 0" />
        <limit effort="10.0" lower="0.0" upper="2.0" velocity="0.5" />
    </joint>
    <link name="arm_3">
        <visual>
            <geometry>
                <mesh filename="package://myrobot5/meshes/link3.dae" />
            </geometry>
            <orgin rpy="0 0 1.5" xyz="0 -.5 0" />
            <material name="blue">
                <color rgba="0 0 0.8 1" />
            </material>
        </visual>
        <collision>
            <geometry>
                <mesh filename="package://myrobot5/meshes/link3.stl" />
            </geometry>
            <orgin rpy="0 0 1.5" xyz="0 -.5 0" />
        </collision>        
        <inertial>
            <mass value="1" />
            <inertia ixx="1.0" ixy="0.0" ixz="0.0" iyy="1.0" iyz="0.0" izz="1.0" />
        </inertial>
    </link>
    <joint name="base_to_arm3" type="revolute">
        <parent link="box" />
        <child link="arm_3" />
        <origin rpy="0 0 1.5" xyz="0 -.5 0" />
        <axis xyz="0 1 0" />
        <limit effort="10.0" lower="0.0" upper="2.0" velocity="0.5" />
    </joint>
    <link name="arm_4">
        <visual>
            <geometry>
                <mesh filename="package://myrobot5/meshes/link3.dae" />
            </geometry>
            <orgin rpy="0 0 -1.5" xyz="0 .5 0" />
            <material name="blue">
                <color rgba="0 0 0.8 1" />
            </material>
        </visual>
        <collision>
            <geometry>
                <mesh filename="package://myrobot5/meshes/link3.stl" />
            </geometry>
            <orgin rpy="0 0 -1.5" xyz="0 .5 0" />
        </collision>        
        <inertial>
            <mass value="1" />
            <inertia ixx="1.0" ixy="0.0" ixz="0.0" iyy="1.0" iyz="0.0" izz="1.0" />
        </inertial>
    </link>
    <joint name="base_to_arm4" type="revolute">
        <parent link="box" />
        <child link="arm_4" />
        <origin rpy="0 0 -1.5" xyz="0 .5 0" />
        <axis xyz="0 1 0" />
        <limit effort="10.0" lower="0.0" upper="2.0" velocity="0.5" />
    </joint>
</robot>


